Workbook

Sheet PANEL
B2: 🏛️ CENTRO DE CONTROL FINANCIERO — MARLON MUÑOZ | H2: 📅 AÑO: | I2: 2026 | K2: 🔍 MES: | L2: octubre
B3: ⚡ Sincronización Automática en Tiempo Real • Bot de Telegram • Facturación Gmail • Nómina y Ahorros Colanta
B5: INGRESO TOTAL DEL MES | E5: GASTO TOTAL DEL MES | H5: AHORRO DEL PERÍODO (COLANTA) | K5: DISPONIBLE LIBRE EN CAJA
B6: =IF(N(H15)>0, H15 + IFERROR(SUMIFS(MOVIMIENTOS!$H$4:$H$246, MOVIMIENTOS!$D$4:$D$246, "Ingreso", MOVIMIENTOS!$E$4:$E$246, "<>Salario", MOVIMIENTOS!$K$4:$K$246, $L$2, MOVIMIENTOS!$L$4:$L$246, $I$2), 0), IFERROR(SUMIFS(MOVIMIENTOS!$H$4:$H$246, MOVIMIENTOS!$D$4:$D$246, "Ingreso", MOVIMIENTOS!$K$4:$K$246, $L$2, MOVIMIENTOS!$L$4:$L$246, $I$2), 0)) -> 0 | E6: =IFERROR(SUMIFS(MOVIMIENTOS!$H$4:$H$246, MOVIMIENTOS!$D$4:$D$246, "Gasto", MOVIMIENTOS!$K$4:$K$246, $L$2, MOVIMIENTOS!$L$4:$L$246, $I$2), 0) -> 207123 | H6: =C16 -> 0 | K6: =B6 - E6 -> -207123
B8: ="⚡ ESTADO FINANCIERO: " & IF(AND(B6=0, E6=0), "⚪ SIN MOVIMIENTOS EN EL MES", IF(K6<=0, "🚨 GASTO SUPERA INGRESOS", IF(K6<300000, "⚠️ CAJA AJUSTADA", "🟢 SALUDABLE Y EN SUPERÁVIT"))) & " | LIQUIDEZ INMEDIATA EN CUENTAS: " & TEXT(J42, "$ #,##0") & " | QUINCENAS SINCRONIZADAS" -> ⚡ ESTADO FINANCIERO: 🚨 GASTO SUPERA INGRESOS | LIQUIDEZ INMEDIATA EN CUENTAS: $ 3,390,857 | QUINCENAS SINCRONIZADAS
B10: AHORROS POR TIPO — FONDO COLANTA | G10: AUDITORÍA NÓMINA COLANTA & FLUJO DE CAJA
B11: Tipo de Ahorro | C11: Mes Seleccionado ($) | D11: Acumulado Total ($) | E11: % Participación | G11: Concepto Nómina / Flujo | H11: Monto ($ COP) | I11: Impacto | J11: Detalle Operativo
B12: Ahorro Ordinario | C12: =AHORROS!B8 -> 0 | D12: =AHORROS!C8 -> 594000 | E12: =AHORROS!D8 -> 0.1510951 | G12: Total Devengado Colanta | H12: =IFERROR(SUMIFS('COLILLAS DE PAGO'!$J$4:$J$22, 'COLILLAS DE PAGO'!$B$4:$B$22, $L$2, 'COLILLAS DE PAGO'!$C$4:$C$22, $I$2), 0) -> 0 | I12: (+) Ingreso Bruto | J12: Salario base + recargos
B13: Ahorro Navideño | C13: =AHORROS!B9 -> 0 | D13: =AHORROS!C9 -> 2160000 | E13: =AHORROS!D9 -> 0.54943671 | G13: Salud y Pensión Ley (8%) | H13: =IFERROR(SUMIFS('COLILLAS DE PAGO'!$K$4:$K$22, 'COLILLAS DE PAGO'!$B$4:$B$22, $L$2, 'COLILLAS DE PAGO'!$C$4:$C$22, $I$2) + SUMIFS('COLILLAS DE PAGO'!$L$4:$L$22, 'COLILLAS DE PAGO'!$B$4:$B$22, $L$2, 'COLILLAS DE PAGO'!$C$4:$C$22, $I$2), 0) -> 0 | I13: (-) Deducción Ley | J13: EPS Sura + Porvenir
B14: Aportes Cooperativos | C14: =AHORROS!B10 -> 0 | D14: =AHORROS!C10 -> 995083 | E14: =AHORROS!D10 -> 0.25311812 | G14: Ahorros Nómina Colanta | H14: =C16 -> 0 | I14: (🐷) Reserva | J14: Deducción Fondo Colanta
B15: Aporte Afiliación / Otros | C15: =AHORROS!B11 -> 0 | D15: =AHORROS!C11 -> 182216 | E15: =AHORROS!D11 -> 0.046350074 | G15: Neto Consignado Colanta | H15: =IFERROR(SUMIFS('COLILLAS DE PAGO'!$O$4:$O$22, 'COLILLAS DE PAGO'!$B$4:$B$22, $L$2, 'COLILLAS DE PAGO'!$C$4:$C$22, $I$2), 0) -> 0 | I15: (=) Consignado | J15: Ingreso efectivo AyC Colanta
B16: TOTAL AHORROS COLANTA | C16: =AHORROS!B12 -> 0 | D16: =AHORROS!C12 -> 3931299 | E16: =AHORROS!D12 -> 1 | G16: Compromisos Fijos Abiertos | H16: =IFERROR('CONTROL FIJOS'!G5, 0) -> 2557000 | I16: (-) Obligación | J16: Pendiente por pagar en el mes
B18: CONTROL PRESUPUESTAL POR CATEGORÍA | I18: INDICADORES DE COBERTURA MENSUAL
B19: Categoría | C19: Gasto Real ($) | D19: Límite ($) | E19: % Uso | F19: Semáforo | G19: Desvío | I19: Total Cuotas Programadas | K19: ='CONTROL FIJOS'!A5 -> 2611000
B20: Alimentación | C20: =SUMIFS(MOVIMIENTOS!$H$4:$H$246, MOVIMIENTOS!$D$4:$D$246, "Gasto", MOVIMIENTOS!$E$4:$E$246, "Alimentaci*", MOVIMIENTOS!$K$4:$K$246, $L$2, MOVIMIENTOS!$L$4:$L$246, $I$2) -> 0 | D20: 800000 | E20: =IF(D20=0, 0, C20/D20) -> 0 | F20: =IF(D20=0, "⚪ Sin límite", IF(E20<=0.8, "🟢 En regla", IF(E20<=1, "🟡 Límite", "🔴 Excedido"))) -> 🟢 En regla | G20: =IF(D20=0, 0, D20-C20) -> 800000 | I20: Total Pagado / Abonado | K20: ='CONTROL FIJOS'!D5 -> 54000
B21: ARRIENDO CASA | C21: =SUMIFS(MOVIMIENTOS!$H$4:$H$246, MOVIMIENTOS!$D$4:$D$246, "Gasto", MOVIMIENTOS!$E$4:$E$246, "Vivienda", MOVIMIENTOS!$K$4:$K$246, $L$2, MOVIMIENTOS!$L$4:$L$246, $I$2)+SUMIFS(MOVIMIENTOS!$H$4:$H$246, MOVIMIENTOS!$D$4:$D$246, "Gasto", MOVIMIENTOS!$E$4:$E$246, "Arriendo Casa", MOVIMIENTOS!$K$4:$K$246, $L$2, MOVIMIENTOS!$L$4:$L$246, $I$2) -> 0 | D21: 900000 | E21: =IF(D21=0, 0, C21/D21) -> 0 | F21: =IF(D21=0, "⚪ Sin límite", IF(E21<=0.8, "🟢 En regla", IF(E21<=1, "🟡 Límite", "🔴 Excedido"))) -> 🟢 En regla | G21: =IF(D21=0, 0, D21-C21) -> 900000 | I21: Saldo Pendiente de Pago | K21: ='CONTROL FIJOS'!G5 -> 2557000
B22: Servicios Públicos | C22: =SUMIFS(MOVIMIENTOS!$H$4:$H$246, MOVIMIENTOS!$D$4:$D$246, "Gasto", MOVIMIENTOS!$E$4:$E$246, "Servicios*", MOVIMIENTOS!$K$4:$K$246, $L$2, MOVIMIENTOS!$L$4:$L$246, $I$2) -> 0 | D22: 300000 | E22: =IF(D22=0, 0, C22/D22) -> 0 | F22: =IF(D22=0, "⚪ Sin límite", IF(E22<=0.8, "🟢 En regla", IF(E22<=1, "🟡 Límite", "🔴 Excedido"))) -> 🟢 En regla | G22: =IF(D22=0, 0, D22-C22) -> 300000 | I22: Obligaciones Pagadas | K22: =COUNTIF('CONTROL FIJOS'!$G$9:$G$26, "🟢 Pagado") -> 2
B23: Transporte y Moto | C23: =SUMIFS(MOVIMIENTOS!$H$4:$H$246, MOVIMIENTOS!$D$4:$D$246, "Gasto", MOVIMIENTOS!$E$4:$E$246, "Transporte*", MOVIMIENTOS!$K$4:$K$246, $L$2, MOVIMIENTOS!$L$4:$L$246, $I$2)+SUMIFS(MOVIMIENTOS!$H$4:$H$246, MOVIMIENTOS!$D$4:$D$246, "Gasto", MOVIMIENTOS!$E$4:$E$246, "Moto", MOVIMIENTOS!$K$4:$K$246, $L$2, MOVIMIENTOS!$L$4:$L$246, $I$2) -> 116000 | D23: 240000 | E23: =IF(D23=0, 0, C23/D23) -> 0.48333333 | F23: =IF(D23=0, "⚪ Sin límite", IF(E23<=0.8, "🟢 En regla", IF(E23<=1, "🟡 Límite", "🔴 Excedido"))) -> 🟢 En regla | G23: =IF(D23=0, 0, D23-C23) -> 124000 | I23: Abonos Parciales | K23: =COUNTIF('CONTROL FIJOS'!$G$9:$G$26, "🟡 Abono Parcial") -> 0
B24: Gastos Hormiga / Dulces | C24: =SUMIFS(MOVIMIENTOS!$H$4:$H$246, MOVIMIENTOS!$D$4:$D$246, "Gasto", MOVIMIENTOS!$E$4:$E$246, "*Hormiga*", MOVIMIENTOS!$K$4:$K$246, $L$2, MOVIMIENTOS!$L$4:$L$246, $I$2)+SUMIFS(MOVIMIENTOS!$H$4:$H$246, MOVIMIENTOS!$D$4:$D$246, "Gasto", MOVIMIENTOS!$E$4:$E$246, "Helado", MOVIMIENTOS!$K$4:$K$246, $L$2, MOVIMIENTOS!$L$4:$L$246, $I$2)+SUMIFS(MOVIMIENTOS!$H$4:$H$246, MOVIMIENTOS!$D$4:$D$246, "Gasto", MOVIMIENTOS!$E$4:$E$246, "Pastillas Garganta", MOVIMIENTOS!$K$4:$K$246, $L$2, MOVIMIENTOS!$L$4:$L$246, $I$2) -> 67000 | D24: 50000 | E24: =IF(D24=0, 0, C24/D24) -> 1.34 | F24: =IF(D24=0, "⚪ Sin límite", IF(E24<=0.8, "🟢 En regla", IF(E24<=1, "🟡 Límite", "🔴 Excedido"))) -> 🔴 Excedido | G24: =IF(D24=0, 0, D24-C24) -> -17000 | I24: Obligaciones Pendientes | K24: =COUNTIF('CONTROL FIJOS'!$G$9:$G$26, "🔴 Pendiente") -> 13
B25: Ocio y Entretenimiento | C25: =SUMIFS(MOVIMIENTOS!$H$4:$H$246, MOVIMIENTOS!$D$4:$D$246, "Gasto", MOVIMIENTOS!$E$4:$E$246, "*Entretenimiento*", MOVIMIENTOS!$F$4:$F$246, "<>Pago fijo", MOVIMIENTOS!$K$4:$K$246, $L$2, MOVIMIENTOS!$L$4:$L$246, $I$2)+SUMIFS(MOVIMIENTOS!$H$4:$H$246, MOVIMIENTOS!$D$4:$D$246, "Gasto", MOVIMIENTOS!$E$4:$E$246, "Ocio*", MOVIMIENTOS!$K$4:$K$246, $L$2, MOVIMIENTOS!$L$4:$L$246, $I$2) -> 14023 | D25: 100000 | E25: =IF(D25=0, 0, C25/D25) -> 0.14023 | F25: =IF(D25=0, "⚪ Sin límite", IF(E25<=0.8, "🟢 En regla", IF(E25<=1, "🟡 Límite", "🔴 Excedido"))) -> 🟢 En regla | G25: =IF(D25=0, 0, D25-C25) -> 85977 | I25: Compromisos Q1 (Día <=15) | K25: =SUMIFS('CONTROL FIJOS'!$I$9:$I$26, 'CONTROL FIJOS'!$D$9:$D$26, "<=15") -> 1332000
B26: Suscripciones | C26: =SUMIFS(MOVIMIENTOS!$H$4:$H$246, MOVIMIENTOS!$D$4:$D$246, "Gasto", MOVIMIENTOS!$E$4:$E$246, "Suscripciones*", MOVIMIENTOS!$K$4:$K$246, $L$2, MOVIMIENTOS!$L$4:$L$246, $I$2)+SUMIFS(MOVIMIENTOS!$H$4:$H$246, MOVIMIENTOS!$D$4:$D$246, "Gasto", MOVIMIENTOS!$E$4:$E$246, "*Entretenimiento*", MOVIMIENTOS!$F$4:$F$246, "Pago fijo", MOVIMIENTOS!$K$4:$K$246, $L$2, MOVIMIENTOS!$L$4:$L$246, $I$2) -> 10100 | D26: 0 | E26: =IF(D26=0, 0, C26/D26) -> 0 | F26: =IF(D26=0, "⚪ Sin límite", IF(E26<=0.8, "🟢 En regla", IF(E26<=1, "🟡 Límite", "🔴 Excedido"))) -> ⚪ Sin límite | G26: =IF(D26=0, 0, D26-C26) -> 0 | I26: Compromisos Q2 (Día >15) | K26: =SUMIFS('CONTROL FIJOS'!$I$9:$I$26, 'CONTROL FIJOS'!$D$9:$D$26, ">15") -> 1225000
B27: Compras | C27: =SUMIFS(MOVIMIENTOS!$H$4:$H$246, MOVIMIENTOS!$D$4:$D$246, "Gasto", MOVIMIENTOS!$E$4:$E$246, "Compras*", MOVIMIENTOS!$K$4:$K$246, $L$2, MOVIMIENTOS!$L$4:$L$246, $I$2) -> 0 | D27: 0 | E27: =IF(D27=0, 0, C27/D27) -> 0 | F27: =IF(D27=0, "⚪ Sin límite", IF(E27<=0.8, "🟢 En regla", IF(E27<=1, "🟡 Límite", "🔴 Excedido"))) -> ⚪ Sin límite | G27: =IF(D27=0, 0, D27-C27) -> 0 | I27: Estado Cobertura Mes | K27: =IF('CONTROL FIJOS'!A5=0, "⚪ Sin Obligaciones", IF('CONTROL FIJOS'!G5=0, "🟢 100% Cubierto", "🟡 Pendiente de Pago")) -> 🟡 Pendiente de Pago
B28: Otras categorías sin presupuesto | C28: =MAX(0, E6-SUM(C20:C27)) -> 0 | D28: 0 | E28: =IF(D28=0, 0, C28/D28) -> 0 | F28: =IF(D28=0, "⚪ Sin límite", IF(E28<=0.8, "🟢 En regla", IF(E28<=1, "🟡 Límite", "🔴 Excedido"))) -> ⚪ Sin límite | G28: =IF(D28=0, 0, D28-C28) -> 0
B30: BALANZA Y FLUJO DE CAJA QUINCENAL ESTIMADO (COLANTA) | I30: RADAR DE GASTOS HORMIGA & FUGAS DEL MES
B31: Período / Quincena | C31: Ingreso Est. ($) | D31: Fijos Est. ($) | E31: Gastos Var. ($) | F31: Caja Libre ($) | G31: Semáforo | I31: Métrica de Control | J31: Monto / Valor | K31: Semáforo | L31: Diagnóstico
B32: Quincena 1 (Día 1-15) | C32: =H15/2 -> 0 | D32: ='CONTROL FIJOS'!J5 -> 1332000 | E32: =IFERROR(SUMIFS(MOVIMIENTOS!$H$4:$H$246, MOVIMIENTOS!$D$4:$D$246, "Gasto", MOVIMIENTOS!$K$4:$K$246, $L$2, MOVIMIENTOS!$L$4:$L$246, $I$2, MOVIMIENTOS!$P$4:$P$246, "Q1"), 0) -> 207123 | F32: =C32-D32-E32 -> -1539123 | G32: =IF(F32>0, "🟢 Superávit", "🔴 Ajustado") -> 🔴 Ajustado | I32: Gasto Hormiga del Mes | J32: =PANEL!C24 -> 67000 | K32: =IF(J32>120000, "🔴 Crítico", IF(J32>50000, "🟡 Moderado", "🟢 Bajo")) -> 🟡 Moderado | L32: Impacto en caja
B33: Quincena 2 (Día 16-30) | C33: =H15/2 -> 0 | D33: ='CONTROL FIJOS'!A5 - 'CONTROL FIJOS'!J5 -> 1279000 | E33: =MAX(0, E6-E32) -> 0 | F33: =C33-D33-E33 -> -1279000 | G33: =IF(F33>0, "🟢 Excedente", "🔴 Ajustado") -> 🔴 Ajustado | I33: N° Compras Hormiga | J33: =IFERROR(COUNTIFS(MOVIMIENTOS!$D$4:$D$246, "Gasto", MOVIMIENTOS!$E$4:$E$246, "*Hormiga*", MOVIMIENTOS!$K$4:$K$246, $L$2, MOVIMIENTOS!$L$4:$L$246, $I$2)+COUNTIFS(MOVIMIENTOS!$D$4:$D$246, "Gasto", MOVIMIENTOS!$E$4:$E$246, "Helado", MOVIMIENTOS!$K$4:$K$246, $L$2, MOVIMIENTOS!$L$4:$L$246, $I$2)+COUNTIFS(MOVIMIENTOS!$D$4:$D$246, "Gasto", MOVIMIENTOS!$E$4:$E$246, "Pastillas Garganta", MOVIMIENTOS!$K$4:$K$246, $L$2, MOVIMIENTOS!$L$4:$L$246, $I$2), 0) -> 2 | K33: =IF(J33>15, "🔴 Frecuente", IF(J33>7, "🟡 Regular", "🟢 Ocasional")) -> 🟢 Ocasional | L33: Frecuencia de compra
B34: Consolidado Mes Libre | C34: =C32+C33 -> 0 | D34: =D32+D33 -> 2611000 | E34: =E32+E33 -> 207123 | F34: =C34-D34-E34 -> -2818123 | G34: =IF(F34>0, "✅ Sostenible", "🚨 Alerta") -> 🚨 Alerta | I34: Ticket Promedio por Antojo | J34: =IF(J33=0, 0, J32/J33) -> 33500 | K34: 📊 Promedio | L34: Costo medio por microgasto
I35: % Impacto vs. Ahorro Colanta | J35: =IF(C16=0, 0, J32/C16) -> 0 | K35: =IF(J35>0.5, "⚠️ Muy Alto", "🟢 Razonable") -> 🟢 Razonable | L35: Equivalente de tu ahorro
B37: 🎄 PROYECCIÓN CIERRE DE AÑO 2026 (FIN DE AÑO MARLON) | I37: 💳 ARQUEO DE LIQUIDEZ POR CUENTA / BOLSILLO
B38: Concepto de Cierre 2026 | C38: Fecha Estimada | D38: Monto Proyectado ($) | F38: Impacto / Destino | I38: Cuenta / Depósito | J38: Monto ($) | K38: Estado | L38: Tipo de Acceso
B39: Entrega Ahorro Navideño Colanta | C39: 01/12/2026 | D39: =AHORROS!C9 -> 2160000 | F39: Liquidación de fondo contractual | I39: 🥛 AyC Colanta (Nómina) | J39: 3319057 | K39: 🟢 Activa | L39: Ahorro / Nómina
B40: Prima Legal de Servicios (Diciembre) | C40: 20/12/2026 | D40: ='COLILLAS DE PAGO'!I26 -> 2418909.1 | F40: Beneficio legal semestral Colanta | I40: 📱 Nequi | J40: 0 | K40: 🟢 Activa | L40: Móvil / Inmediato
B41: Ahorros Totales Colanta Acumulados | C41: 31/12/2026 | D41: =AHORROS!C12 -> 3931299 | F41: Patrimonio acumulado en la cooperativa | I41: 💵 Efectivo | J41: 71800 | K41: 🟢 Disponible | L41: Efectivo Mano
B42: Total Liquidez Extra Proyectada Diciembre | C42: 31/12/2026 | D42: =D39+D40 -> 4578909.1 | F42: Capital disponible fin de año | I42: 📦 Total Liquidez Inmediata | J42: =SUM(J39:J41) -> 3390857 | K42: 💎 Consolidado | L42: Disponibilidad Total

Sheet MOVIMIENTOS
A1: 💳 REGISTRO MAESTRO DE MOVIMIENTOS
A2: Bitácora contable sincronizada con bot de Telegram y clasificación automática de gastos.
A4: ID | B4: Fecha | C4: Hora | D4: Tipo | E4: Categoría | F4: Subcategoría | G4: Descripción | H4: Valor ($ COP) | I4: Método de Pago | J4: Cuenta / Origen | K4: Mes | L4: Año | M4: Comprobante / Ref | N4: Notas | O4: _IndexFiltro | P4: Quincena
A5: M-0255 | B5: 46310 | C5: 05:58 PM | D5: Gasto | E5: Entretenimiento | F5: Pago fijo | G5: Spotify - Factura octubre 2026 | H5: 10100 | I5: Tarjeta Nequi | J5: Nequi | K5: octubre | L5: 2026 | M5: Gmail | N5: PAGO_FIJO|F-0114|octubre|2026|REF:GPA.3333-4099-9556-15284..13 | O5: =IF(ISBLANK(A5), "", IF(AND(LOWER(TRIM(K5))=LOWER(TRIM(PANEL!$L$2)), L5=PANEL!$I$2), MAX($O$4:O4)+1, "")) -> 1 | P5: =IF(ISBLANK(A5), "", IF(OR(B5="Q1", B5="Q2"), B5, IF(ISNUMBER(B5), IF(DAY(B5)<=15, "Q1", "Q2"), IF(MID(TRIM(B5),3,1)="/", IF(VALUE(LEFT(TRIM(B5),2))<=15, "Q1", "Q2"), IF(MID(TRIM(B5),5,1)="-", IF(VALUE(MID(TRIM(B5),9,2))<=15, "Q1", "Q2"), "Q1"))))) -> Q1
A6: M-0242 | B6: 46302 | C6: 01:22 PM | D6: Gasto | E6: Entretenimiento | F6: Videojuegos / Eneba | G6: Compra en Eneba por E-Wallet / EBANX | H6: 14023 | I6: Tarjeta | J6: Bancolombia | K6: octubre | L6: 2026 | M6: Gmail | N6: GMAIL:1a117998a2bbdde6|REF:783dcfda-c27b-11f1-8fdf-6e753a749966 | O6: =IF(ISBLANK(A6), "", IF(AND(LOWER(TRIM(K6))=LOWER(TRIM(PANEL!$L$2)), L6=PANEL!$I$2), MAX($O$4:O5)+1, "")) -> 2 | P6: =IF(ISBLANK(A6), "", IF(OR(B6="Q1", B6="Q2"), B6, IF(ISNUMBER(B6), IF(DAY(B6)<=15, "Q1", "Q2"), IF(MID(TRIM(B6),3,1)="/", IF(VALUE(LEFT(TRIM(B6),2))<=15, "Q1", "Q2"), IF(MID(TRIM(B6),5,1)="-", IF(VALUE(MID(TRIM(B6),9,2))<=15, "Q1", "Q2"), "Q1"))))) -> Q1
A7: M-0241 | B7: 46301 | C7: 07:07 PM | D7: Gasto | E7: Moto | F7: Mantenimiento | G7: Lavada de Moto | H7: 19000 | I7: Transferencia | J7: Nequi | K7: octubre | L7: 2026 | M7: Telegram | O7: =IF(ISBLANK(A7), "", IF(AND(LOWER(TRIM(K7))=LOWER(TRIM(PANEL!$L$2)), L7=PANEL!$I$2), MAX($O$4:O6)+1, "")) -> 3 | P7: =IF(ISBLANK(A7), "", IF(OR(B7="Q1", B7="Q2"), B7, IF(ISNUMBER(B7), IF(DAY(B7)<=15, "Q1", "Q2"), IF(MID(TRIM(B7),3,1)="/", IF(VALUE(LEFT(TRIM(B7),2))<=15, "Q1", "Q2"), IF(MID(TRIM(B7),5,1)="-", IF(VALUE(MID(TRIM(B7),9,2))<=15, "Q1", "Q2"), "Q1"))))) -> Q1
A8: M-0240 | B8: 46301 | C8: 07:07 PM | D8: Gasto | E8: Moto | F8: Gasolina | G8: Tanqueada de Gasolina para Moto | H8: 31000 | I8: Transferencia | J8: Nequi | K8: octubre | L8: 2026 | M8: Telegram | O8: =IF(ISBLANK(A8), "", IF(AND(LOWER(TRIM(K8))=LOWER(TRIM(PANEL!$L$2)), L8=PANEL!$I$2), MAX($O$4:O7)+1, "")) -> 4 | P8: =IF(ISBLANK(A8), "", IF(OR(B8="Q1", B8="Q2"), B8, IF(ISNUMBER(B8), IF(DAY(B8)<=15, "Q1", "Q2"), IF(MID(TRIM(B8),3,1)="/", IF(VALUE(LEFT(TRIM(B8),2))<=15, "Q1", "Q2"), IF(MID(TRIM(B8),5,1)="-", IF(VALUE(MID(TRIM(B8),9,2))<=15, "Q1", "Q2"), "Q1"))))) -> Q1
A9: M-0238 | B9: 46297 | C9: 10:09 PM | D9: Gasto | E9: Moto | F9: Gasolina | G9: Gasolina moto | H9: 33000 | I9: Transferencia | J9: Nequi | K9: octubre | L9: 2026 | M9: Telegram | O9: =IF(ISBLANK(A9), "", IF(AND(LOWER(TRIM(K9))=LOWER(TRIM(PANEL!$L$2)), L9=PANEL!$I$2), MAX($O$4:O8)+1, "")) -> 5 | P9: =IF(ISBLANK(A9), "", IF(OR(B9="Q1", B9="Q2"), B9, IF(ISNUMBER(B9), IF(DAY(B9)<=15, "Q1", "Q2"), IF(MID(TRIM(B9),3,1)="/", IF(VALUE(LEFT(TRIM(B9),2))<=15, "Q1", "Q2"), IF(MID(TRIM(B9),5,1)="-", IF(VALUE(MID(TRIM(B9),9,2))<=15, "Q1", "Q2"), "Q1"))))) -> Q1
A10: M-0237 | B10: 46297 | C10: 09:57 PM | D10: Gasto | E10: Gastos Hormiga / Dulces | F10: General | G10: Endulzada de amigo secreto | H10: 33000 | I10: Efectivo | J10: Efectivo | K10: octubre | L10: 2026 | M10: Telegram | O10: =IF(ISBLANK(A10), "", IF(AND(LOWER(TRIM(K10))=LOWER(TRIM(PANEL!$L$2)), L10=PANEL!$I$2), MAX($O$4:O9)+1, "")) -> 6 | P10: =IF(ISBLANK(A10), "", IF(OR(B10="Q1", B10="Q2"), B10, IF(ISNUMBER(B10), IF(DAY(B10)<=15, "Q1", "Q2"), IF(MID(TRIM(B10),3,1)="/", IF(VALUE(LEFT(TRIM(B10),2))<=15, "Q1", "Q2"), IF(MID(TRIM(B10),5,1)="-", IF(VALUE(MID(TRIM(B10),9,2))<=15, "Q1", "Q2"), "Q1"))))) -> Q1
A11: M-0235 | B11: 46295 | C11: 09:40 PM | D11: Gasto | E11: Vivienda | F11: Pago fijo | G11: ARRIENDO CASA - Factura septiembre 2026 | H11: 900000 | I11: Transferencia | J11: Nequi | K11: septiembre | L11: 2026 | M11: Telegram | N11: PAGO_FIJO|F-0101|septiembre|2026 | O11: =IF(ISBLANK(A11), "", IF(AND(LOWER(TRIM(K11))=LOWER(TRIM(PANEL!$L$2)), L11=PANEL!$I$2), MAX($O$4:O10)+1, "")) | P11: =IF(ISBLANK(A11), "", IF(OR(B11="Q1", B11="Q2"), B11, IF(ISNUMBER(B11), IF(DAY(B11)<=15, "Q1", "Q2"), IF(MID(TRIM(B11),3,1)="/", IF(VALUE(LEFT(TRIM(B11),2))<=15, "Q1", "Q2"), IF(MID(TRIM(B11),5,1)="-", IF(VALUE(MID(TRIM(B11),9,2))<=15, "Q1", "Q2"), "Q1"))))) -> Q2
A12: M-0234 | B12: 46295 | C12: 09:38 PM | D12: Gasto | E12: Servicios | F12: Pago fijo | G12: CUOTA DATOS CELULAR - Factura septiembre 2026 | H12: 43900 | I12: Transferencia | J12: Nequi | K12: septiembre | L12: 2026 | M12: Telegram | N12: PAGO_FIJO|F-0100|septiembre|2026 | O12: =IF(ISBLANK(A12), "", IF(AND(LOWER(TRIM(K12))=LOWER(TRIM(PANEL!$L$2)), L12=PANEL!$I$2), MAX($O$4:O11)+1, "")) | P12: =IF(ISBLANK(A12), "", IF(OR(B12="Q1", B12="Q2"), B12, IF(ISNUMBER(B12), IF(DAY(B12)<=15, "Q1", "Q2"), IF(MID(TRIM(B12),3,1)="/", IF(VALUE(LEFT(TRIM(B12),2))<=15, "Q1", "Q2"), IF(MID(TRIM(B12),5,1)="-", IF(VALUE(MID(TRIM(B12),9,2))<=15, "Q1", "Q2"), "Q1"))))) -> Q2
A13: M-0233 | B13: 46297 | C13: 12:54 PM | D13: Gasto | E13: Gastos Hormiga / Dulces | F13: General | G13: Endulzada | H13: 34000 | I13: Efectivo | J13: Efectivo | K13: octubre | L13: 2026 | M13: Telegram | O13: =IF(ISBLANK(A13), "", IF(AND(LOWER(TRIM(K13))=LOWER(TRIM(PANEL!$L$2)), L13=PANEL!$I$2), MAX($O$4:O12)+1, "")) -> 7 | P13: =IF(ISBLANK(A13), "", IF(OR(B13="Q1", B13="Q2"), B13, IF(ISNUMBER(B13), IF(DAY(B13)<=15, "Q1", "Q2"), IF(MID(TRIM(B13),3,1)="/", IF(VALUE(LEFT(TRIM(B13),2))<=15, "Q1", "Q2"), IF(MID(TRIM(B13),5,1)="-", IF(VALUE(MID(TRIM(B13),9,2))<=15, "Q1", "Q2"), "Q1"))))) -> Q1
A14: M-0232 | B14: 46296 | C14: 09:42 PM | D14: Gasto | E14: Moto | F14: Gasolina | G14: Gasolina para moto | H14: 33000 | I14: Transferencia | J14: Nequi | K14: octubre | L14: 2026 | M14: Telegram | O14: =IF(ISBLANK(A14), "", IF(AND(LOWER(TRIM(K14))=LOWER(TRIM(PANEL!$L$2)), L14=PANEL!$I$2), MAX($O$4:O13)+1, "")) -> 8 | P14: =IF(ISBLANK(A14), "", IF(OR(B14="Q1", B14="Q2"), B14, IF(ISNUMBER(B14), IF(DAY(B14)<=15, "Q1", "Q2"), IF(MID(TRIM(B14),3,1)="/", IF(VALUE(LEFT(TRIM(B14),2))<=15, "Q1", "Q2"), IF(MID(TRIM(B14),5,1)="-", IF(VALUE(MID(TRIM(B14),9,2))<=15, "Q1", "Q2"), "Q1"))))) -> Q1
A15: M-0230 | B15: Q1 | C15: 08:22 PM | D15: Ingreso | E15: Salario | F15: Nómina | G15: Nómina Colanta | H15: 2339862 | I15: Transferencia / Nómina | J15: Colilla_Enero_Q1.pdf | K15: enero | L15: 2026 | M15: Telegram | N15: Ref Colilla: CP-0003 | O15: =IF(ISBLANK(A15), "", IF(AND(LOWER(TRIM(K15))=LOWER(TRIM(PANEL!$L$2)), L15=PANEL!$I$2), MAX($O$4:O14)+1, "")) | P15: =IF(ISBLANK(A15), "", IF(OR(B15="Q1", B15="Q2"), B15, IF(ISNUMBER(B15), IF(DAY(B15)<=15, "Q1", "Q2"), IF(MID(TRIM(B15),3,1)="/", IF(VALUE(LEFT(TRIM(B15),2))<=15, "Q1", "Q2"), IF(MID(TRIM(B15),5,1)="-", IF(VALUE(MID(TRIM(B15),9,2))<=15, "Q1", "Q2"), "Q1"))))) -> Q1
A16: M-0229 | B16: Q2 | C16: 08:22 PM | D16: Ingreso | E16: Salario | F16: Nómina | G16: Nómina Colanta | H16: 1502360 | I16: Transferencia / Nómina | J16: Colilla_Enero_Q2.pdf | K16: enero | L16: 2026 | M16: Telegram | N16: Ref Colilla: CP-0002 | O16: =IF(ISBLANK(A16), "", IF(AND(LOWER(TRIM(K16))=LOWER(TRIM(PANEL!$L$2)), L16=PANEL!$I$2), MAX($O$4:O15)+1, "")) | P16: =IF(ISBLANK(A16), "", IF(OR(B16="Q1", B16="Q2"), B16, IF(ISNUMBER(B16), IF(DAY(B16)<=15, "Q1", "Q2"), IF(MID(TRIM(B16),3,1)="/", IF(VALUE(LEFT(TRIM(B16),2))<=15, "Q1", "Q2"), IF(MID(TRIM(B16),5,1)="-", IF(VALUE(MID(TRIM(B16),9,2))<=15, "Q1", "Q2"), "Q1"))))) -> Q2
A17: M-0228 | B17: Q1 | C17: 08:22 PM | D17: Ingreso | E17: Salario | F17: Nómina | G17: Nómina Colanta | H17: 1687372 | I17: Transferencia / Nómina | J17: Colilla_Febrero_Q1.pdf | K17: febrero | L17: 2026 | M17: Telegram | N17: Ref Colilla: CP-0005 | O17: =IF(ISBLANK(A17), "", IF(AND(LOWER(TRIM(K17))=LOWER(TRIM(PANEL!$L$2)), L17=PANEL!$I$2), MAX($O$4:O16)+1, "")) | P17: =IF(ISBLANK(A17), "", IF(OR(B17="Q1", B17="Q2"), B17, IF(ISNUMBER(B17), IF(DAY(B17)<=15, "Q1", "Q2"), IF(MID(TRIM(B17),3,1)="/", IF(VALUE(LEFT(TRIM(B17),2))<=15, "Q1", "Q2"), IF(MID(TRIM(B17),5,1)="-", IF(VALUE(MID(TRIM(B17),9,2))<=15, "Q1", "Q2"), "Q1"))))) -> Q1
A18: M-0227 | B18: Q2 | C18: 08:22 PM | D18: Ingreso | E18: Salario | F18: Nómina | G18: Nómina Colanta | H18: 1046300 | I18: Transferencia / Nómina | J18: Colilla_Febrero_Q2.pdf | K18: febrero | L18: 2026 | M18: Telegram | N18: Ref Colilla: CP-0004 | O18: =IF(ISBLANK(A18), "", IF(AND(LOWER(TRIM(K18))=LOWER(TRIM(PANEL!$L$2)), L18=PANEL!$I$2), MAX($O$4:O17)+1, "")) | P18: =IF(ISBLANK(A18), "", IF(OR(B18="Q1", B18="Q2"), B18, IF(ISNUMBER(B18), IF(DAY(B18)<=15, "Q1", "Q2"), IF(MID(TRIM(B18),3,1)="/", IF(VALUE(LEFT(TRIM(B18),2))<=15, "Q1", "Q2"), IF(MID(TRIM(B18),5,1)="-", IF(VALUE(MID(TRIM(B18),9,2))<=15, "Q1", "Q2"), "Q1"))))) -> Q2
A19: M-0226 | B19: Q1 | C19: 08:22 PM | D19: Ingreso | E19: Salario | F19: Nómina | G19: Nómina Colanta | H19: 1750495 | I19: Transferencia / Nómina | J19: Colilla_Marzo_Q1.pdf | K19: marzo | L19: 2026 | M19: Telegram | N19: Ref Colilla: CP-0011 | O19: =IF(ISBLANK(A19), "", IF(AND(LOWER(TRIM(K19))=LOWER(TRIM(PANEL!$L$2)), L19=PANEL!$I$2), MAX($O$4:O18)+1, "")) | P19: =IF(ISBLANK(A19), "", IF(OR(B19="Q1", B19="Q2"), B19, IF(ISNUMBER(B19), IF(DAY(B19)<=15, "Q1", "Q2"), IF(MID(TRIM(B19),3,1)="/", IF(VALUE(LEFT(TRIM(B19),2))<=15, "Q1", "Q2"), IF(MID(TRIM(B19),5,1)="-", IF(VALUE(MID(TRIM(B19),9,2))<=15, "Q1", "Q2"), "Q1"))))) -> Q1
A20: M-0225 | B20: Q2 | C20: 08:22 PM | D20: Ingreso | E20: Salario | F20: Nómina | G20: Nómina Colanta | H20: 1758916 | I20: Transferencia / Nómina | J20: Colilla_Marzo_Q2.pdf | K20: marzo | L20: 2026 | M20: Telegram | N20: Ref Colilla: CP-0012 | O20: =IF(ISBLANK(A20), "", IF(AND(LOWER(TRIM(K20))=LOWER(TRIM(PANEL!$L$2)), L20=PANEL!$I$2), MAX($O$4:O19)+1, "")) | P20: =IF(ISBLANK(A20), "", IF(OR(B20="Q1", B20="Q2"), B20, IF(ISNUMBER(B20), IF(DAY(B20)<=15, "Q1", "Q2"), IF(MID(TRIM(B20),3,1)="/", IF(VALUE(LEFT(TRIM(B20),2))<=15, "Q1", "Q2"), IF(MID(TRIM(B20),5,1)="-", IF(VALUE(MID(TRIM(B20),9,2))<=15, "Q1", "Q2"), "Q1"))))) -> Q2
A21: M-0224 | B21: Q1 | C21: 08:22 PM | D21: Ingreso | E21: Salario | F21: Nómina | G21: Nómina Colanta | H21: 1918622 | I21: Transferencia / Nómina | J21: Colilla_Abril_Q1.pdf | K21: abril | L21: 2026 | M21: Telegram | N21: Ref Colilla: CP-0013 | O21: =IF(ISBLANK(A21), "", IF(AND(LOWER(TRIM(K21))=LOWER(TRIM(PANEL!$L$2)), L21=PANEL!$I$2), MAX($O$4:O20)+1, "")) | P21: =IF(ISBLANK(A21), "", IF(OR(B21="Q1", B21="Q2"), B21, IF(ISNUMBER(B21), IF(DAY(B21)<=15, "Q1", "Q2"), IF(MID(TRIM(B21),3,1)="/", IF(VALUE(LEFT(TRIM(B21),2))<=15, "Q1", "Q2"), IF(MID(TRIM(B21),5,1)="-", IF(VALUE(MID(TRIM(B21),9,2))<=15, "Q1", "Q2"), "Q1"))))) -> Q1
A22: M-0223 | B22: Q2 | C22: 08:22 PM | D22: Ingreso | E22: Salario | F22: Nómina | G22: Nómina Colanta | H22: 1575490 | I22: Transferencia / Nómina | J22: Colilla_Abril_Q2.pdf | K22: abril | L22: 2026 | M22: Telegram | N22: Ref Colilla: CP-0014 | O22: =IF(ISBLANK(A22), "", IF(AND(LOWER(TRIM(K22))=LOWER(TRIM(PANEL!$L$2)), L22=PANEL!$I$2), MAX($O$4:O21)+1, "")) | P22: =IF(ISBLANK(A22), "", IF(OR(B22="Q1", B22="Q2"), B22, IF(ISNUMBER(B22), IF(DAY(B22)<=15, "Q1", "Q2"), IF(MID(TRIM(B22),3,1)="/", IF(VALUE(LEFT(TRIM(B22),2))<=15, "Q1", "Q2"), IF(MID(TRIM(B22),5,1)="-", IF(VALUE(MID(TRIM(B22),9,2))<=15, "Q1", "Q2"), "Q1"))))) -> Q2
A23: M-0222 | B23: Q1 | C23: 08:22 PM | D23: Ingreso | E23: Salario | F23: Nómina | G23: Nómina Colanta | H23: 1637623 | I23: Transferencia / Nómina | J23: Colilla_Mayo_Q1.pdf | K23: mayo | L23: 2026 | M23: Telegram | N23: Ref Colilla: CP-0015 | O23: =IF(ISBLANK(A23), "", IF(AND(LOWER(TRIM(K23))=LOWER(TRIM(PANEL!$L$2)), L23=PANEL!$I$2), MAX($O$4:O22)+1, "")) | P23: =IF(ISBLANK(A23), "", IF(OR(B23="Q1", B23="Q2"), B23, IF(ISNUMBER(B23), IF(DAY(B23)<=15, "Q1", "Q2"), IF(MID(TRIM(B23),3,1)="/", IF(VALUE(LEFT(TRIM(B23),2))<=15, "Q1", "Q2"), IF(MID(TRIM(B23),5,1)="-", IF(VALUE(MID(TRIM(B23),9,2))<=15, "Q1", "Q2"), "Q1"))))) -> Q1
A24: M-0221 | B24: Q2 | C24: 08:22 PM | D24: Ingreso | E24: Salario | F24: Nómina | G24: Nómina Colanta | H24: 1526130 | I24: Transferencia / Nómina | J24: Colilla_Mayo_Q2.pdf | K24: mayo | L24: 2026 | M24: Telegram | N24: Ref Colilla: CP-0006 | O24: =IF(ISBLANK(A24), "", IF(AND(LOWER(TRIM(K24))=LOWER(TRIM(PANEL!$L$2)), L24=PANEL!$I$2), MAX($O$4:O23)+1, "")) | P24: =IF(ISBLANK(A24), "", IF(OR(B24="Q1", B24="Q2"), B24, IF(ISNUMBER(B24), IF(DAY(B24)<=15, "Q1", "Q2"), IF(MID(TRIM(B24),3,1)="/", IF(VALUE(LEFT(TRIM(B24),2))<=15, "Q1", "Q2"), IF(MID(TRIM(B24),5,1)="-", IF(VALUE(MID(TRIM(B24),9,2))<=15, "Q1", "Q2"), "Q1"))))) -> Q2
A25: M-0220 | B25: Q1 | C25: 08:22 PM | D25: Ingreso | E25: Salario | F25: Nómina | G25: Nómina Colanta | H25: 3519208 | I25: Transferencia / Nómina | J25: Colilla_Junio_Q1_Prima.pdf | K25: junio | L25: 2026 | M25: Telegram | N25: Ref Colilla: CP-0016 | O25: =IF(ISBLANK(A25), "", IF(AND(LOWER(TRIM(K25))=LOWER(TRIM(PANEL!$L$2)), L25=PANEL!$I$2), MAX($O$4:O24)+1, "")) | P25: =IF(ISBLANK(A25), "", IF(OR(B25="Q1", B25="Q2"), B25, IF(ISNUMBER(B25), IF(DAY(B25)<=15, "Q1", "Q2"), IF(MID(TRIM(B25),3,1)="/", IF(VALUE(LEFT(TRIM(B25),2))<=15, "Q1", "Q2"), IF(MID(TRIM(B25),5,1)="-", IF(VALUE(MID(TRIM(B25),9,2))<=15, "Q1", "Q2"), "Q1"))))) -> Q1
A26: M-0219 | B26: Q2 | C26: 08:22 PM | D26: Ingreso | E26: Salario | F26: Nómina | G26: Nómina Colanta | H26: 1938906 | I26: Transferencia / Nómina | J26: Colilla_Junio_Q2.pdf | K26: junio | L26: 2026 | M26: Telegram | N26: Ref Colilla: CP-0017 | O26: =IF(ISBLANK(A26), "", IF(AND(LOWER(TRIM(K26))=LOWER(TRIM(PANEL!$L$2)), L26=PANEL!$I$2), MAX($O$4:O25)+1, "")) | P26: =IF(ISBLANK(A26), "", IF(OR(B26="Q1", B26="Q2"), B26, IF(ISNUMBER(B26), IF(DAY(B26)<=15, "Q1", "Q2"), IF(MID(TRIM(B26),3,1)="/", IF(VALUE(LEFT(TRIM(B26),2))<=15, "Q1", "Q2"), IF(MID(TRIM(B26),5,1)="-", IF(VALUE(MID(TRIM(B26),9,2))<=15, "Q1", "Q2"), "Q1"))))) -> Q2
... A31: M-0214 | B31: Q1 | C31: 08:21 PM | D31: Ingreso | E31: Salario | F31: Nómina | G31: Nómina Colanta | H31: 1702727 | I31: Transferencia / Nómina | J31: Colilla_Pago_Periodo_17.pdf | K31: septiembre | L31: 2026 | M31: Telegram | N31: Ref Colilla: CP-0010 | O31: =IF(ISBLANK(A31), "", IF(AND(LOWER(TRIM(K31))=LOWER(TRIM(PANEL!$L$2)), L31=PANEL!$I$2), MAX($O$4:O30)+1, "")) | P31: =IF(ISBLANK(A31), "", IF(OR(B31="Q1", B31="Q2"), B31, IF(ISNUMBER(B31), IF(DAY(B31)<=15, "Q1", "Q2"), IF(MID(TRIM(B31),3,1)="/", IF(VALUE(LEFT(TRIM(B31),2))<=15, "Q1", "Q2"), IF(MID(TRIM(B31),5,1)="-", IF(VALUE(MID(TRIM(B31),9,2))<=15, "Q1", "Q2"), "Q1"))))) -> Q1
A32: M-0212 | B32: 46295 | C32: 04:24 PM | D32: Gasto | E32: Transporte | F32: Parqueadero | G32: Parqueadero semanal | H32: 8500 | I32: No especificado | J32: No especificada | K32: septiembre | L32: 2026 | M32: Telegram | O32: =IF(ISBLANK(A32), "", IF(AND(LOWER(TRIM(K32))=LOWER(TRIM(PANEL!$L$2)), L32=PANEL!$I$2), MAX($O$4:O31)+1, "")) | P32: =IF(ISBLANK(A32), "", IF(OR(B32="Q1", B32="Q2"), B32, IF(ISNUMBER(B32), IF(DAY(B32)<=15, "Q1", "Q2"), IF(MID(TRIM(B32),3,1)="/", IF(VALUE(LEFT(TRIM(B32),2))<=15, "Q1", "Q2"), IF(MID(TRIM(B32),5,1)="-", IF(VALUE(MID(TRIM(B32),9,2))<=15, "Q1", "Q2"), "Q1"))))) -> Q2
A33: M-0210 | B33: 46293 | C33: 06:40 PM | D33: Gasto | E33: Gastos Hormiga / Dulces | F33: General | G33: Mecato en tiendas | H33: 13200 | I33: No especificado | J33: No especificada | K33: septiembre | L33: 2026 | M33: Telegram | O33: =IF(ISBLANK(A33), "", IF(AND(LOWER(TRIM(K33))=LOWER(TRIM(PANEL!$L$2)), L33=PANEL!$I$2), MAX($O$4:O32)+1, "")) | P33: =IF(ISBLANK(A33), "", IF(OR(B33="Q1", B33="Q2"), B33, IF(ISNUMBER(B33), IF(DAY(B33)<=15, "Q1", "Q2"), IF(MID(TRIM(B33),3,1)="/", IF(VALUE(LEFT(TRIM(B33),2))<=15, "Q1", "Q2"), IF(MID(TRIM(B33),5,1)="-", IF(VALUE(MID(TRIM(B33),9,2))<=15, "Q1", "Q2"), "Q1"))))) -> Q2
A34: M-0209 | B34: 46293 | C34: 03:20 PM | D34: Gasto | E34: Transporte | F34: General | G34: 8500 parqueadero trabajo | H34: 8500 | I34: No especificado | J34: No especificada | K34: septiembre | L34: 2026 | M34: Telegram | O34: =IF(ISBLANK(A34), "", IF(AND(LOWER(TRIM(K34))=LOWER(TRIM(PANEL!$L$2)), L34=PANEL!$I$2), MAX($O$4:O33)+1, "")) | P34: =IF(ISBLANK(A34), "", IF(OR(B34="Q1", B34="Q2"), B34, IF(ISNUMBER(B34), IF(DAY(B34)<=15, "Q1", "Q2"), IF(MID(TRIM(B34),3,1)="/", IF(VALUE(LEFT(TRIM(B34),2))<=15, "Q1", "Q2"), IF(MID(TRIM(B34),5,1)="-", IF(VALUE(MID(TRIM(B34),9,2))<=15, "Q1", "Q2"), "Q1"))))) -> Q2
A35: M-0208 | B35: 46291 | C35: 01:33 PM | D35: Gasto | E35: Otros | F35: General | G35: 80 mil gastos concierto feid | H35: 80000 | I35: No especificado | J35: No especificada | K35: septiembre | L35: 2026 | M35: Telegram | O35: =IF(ISBLANK(A35), "", IF(AND(LOWER(TRIM(K35))=LOWER(TRIM(PANEL!$L$2)), L35=PANEL!$I$2), MAX($O$4:O34)+1, "")) | P35: =IF(ISBLANK(A35), "", IF(OR(B35="Q1", B35="Q2"), B35, IF(ISNUMBER(B35), IF(DAY(B35)<=15, "Q1", "Q2"), IF(MID(TRIM(B35),3,1)="/", IF(VALUE(LEFT(TRIM(B35),2))<=15, "Q1", "Q2"), IF(MID(TRIM(B35),5,1)="-", IF(VALUE(MID(TRIM(B35),9,2))<=15, "Q1", "Q2"), "Q1"))))) -> Q2
A36: M-0207 | B36: 46290 | C36: 02:05 PM | D36: Gasto | E36: Otros | F36: General | G36: 22 mil pesos corte cabello | H36: 22000 | I36: No especificado | J36: No especificada | K36: septiembre | L36: 2026 | M36: Telegram | O36: =IF(ISBLANK(A36), "", IF(AND(LOWER(TRIM(K36))=LOWER(TRIM(PANEL!$L$2)), L36=PANEL!$I$2), MAX($O$4:O35)+1, "")) | P36: =IF(ISBLANK(A36), "", IF(OR(B36="Q1", B36="Q2"), B36, IF(ISNUMBER(B36), IF(DAY(B36)<=15, "Q1", "Q2"), IF(MID(TRIM(B36),3,1)="/", IF(VALUE(LEFT(TRIM(B36),2))<=15, "Q1", "Q2"), IF(MID(TRIM(B36),5,1)="-", IF(VALUE(MID(TRIM(B36),9,2))<=15, "Q1", "Q2"), "Q1"))))) -> Q2
A37: M-0206 | B37: 46290 | C37: 11:43 AM | D37: Gasto | E37: Otros | F37: General | G37: 8 mil recarga cívica metro | H37: 8000 | I37: No especificado | J37: No especificada | K37: septiembre | L37: 2026 | M37: Telegram | O37: =IF(ISBLANK(A37), "", IF(AND(LOWER(TRIM(K37))=LOWER(TRIM(PANEL!$L$2)), L37=PANEL!$I$2), MAX($O$4:O36)+1, "")) | P37: =IF(ISBLANK(A37), "", IF(OR(B37="Q1", B37="Q2"), B37, IF(ISNUMBER(B37), IF(DAY(B37)<=15, "Q1", "Q2"), IF(MID(TRIM(B37),3,1)="/", IF(VALUE(LEFT(TRIM(B37),2))<=15, "Q1", "Q2"), IF(MID(TRIM(B37),5,1)="-", IF(VALUE(MID(TRIM(B37),9,2))<=15, "Q1", "Q2"), "Q1"))))) -> Q2
A38: M-0205 | B38: 46290 | C38: 11:43 AM | D38: Gasto | E38: Moto | F38: General | G38: 8 mil didi moto transporte | H38: 8000 | I38: No especificado | J38: No especificada | K38: septiembre | L38: 2026 | M38: Telegram | O38: =IF(ISBLANK(A38), "", IF(AND(LOWER(TRIM(K38))=LOWER(TRIM(PANEL!$L$2)), L38=PANEL!$I$2), MAX($O$4:O37)+1, "")) | P38: =IF(ISBLANK(A38), "", IF(OR(B38="Q1", B38="Q2"), B38, IF(ISNUMBER(B38), IF(DAY(B38)<=15, "Q1", "Q2"), IF(MID(TRIM(B38),3,1)="/", IF(VALUE(LEFT(TRIM(B38),2))<=15, "Q1", "Q2"), IF(MID(TRIM(B38),5,1)="-", IF(VALUE(MID(TRIM(B38),9,2))<=15, "Q1", "Q2"), "Q1"))))) -> Q2
A39: M-0204 | B39: 46289 | C39: 05:37 AM | D39: Gasto | E39: Moto | F39: General | G39: 90 mil arreglo moto | H39: 90000 | I39: No especificado | J39: No especificada | K39: septiembre | L39: 2026 | M39: Telegram | O39: =IF(ISBLANK(A39), "", IF(AND(LOWER(TRIM(K39))=LOWER(TRIM(PANEL!$L$2)), L39=PANEL!$I$2), MAX($O$4:O38)+1, "")) | P39: =IF(ISBLANK(A39), "", IF(OR(B39="Q1", B39="Q2"), B39, IF(ISNUMBER(B39), IF(DAY(B39)<=15, "Q1", "Q2"), IF(MID(TRIM(B39),3,1)="/", IF(VALUE(LEFT(TRIM(B39),2))<=15, "Q1", "Q2"), IF(MID(TRIM(B39),5,1)="-", IF(VALUE(MID(TRIM(B39),9,2))<=15, "Q1", "Q2"), "Q1"))))) -> Q2
A40: M-0203 | B40: 46288 | C40: 07:50 PM | D40: Gasto | E40: Moto | F40: General | G40: 31 mil pesos gasolina moto | H40: 31000 | I40: No especificado | J40: No especificada | K40: septiembre | L40: 2026 | M40: Telegram | O40: =IF(ISBLANK(A40), "", IF(AND(LOWER(TRIM(K40))=LOWER(TRIM(PANEL!$L$2)), L40=PANEL!$I$2), MAX($O$4:O39)+1, "")) | P40: =IF(ISBLANK(A40), "", IF(OR(B40="Q1", B40="Q2"), B40, IF(ISNUMBER(B40), IF(DAY(B40)<=15, "Q1", "Q2"), IF(MID(TRIM(B40),3,1)="/", IF(VALUE(LEFT(TRIM(B40),2))<=15, "Q1", "Q2"), IF(MID(TRIM(B40),5,1)="-", IF(VALUE(MID(TRIM(B40),9,2))<=15, "Q1", "Q2"), "Q1"))))) -> Q2
A41: M-0202 | B41: 46288 | C41: 06:29 PM | D41: Gasto | E41: Alimentación | F41: Lácteos y Colanta | G41: Factura Electrónica DIAN COOPERATIVA COLANTA 804P222666 | H41: 11950 | I41: Transferencia | J41: AyC Colanta | K41: septiembre | L41: 2026 | M41: Gmail | N41: GMAIL:1a0d095b21a6f468|REF:804P222666 | O41: =IF(ISBLANK(A41), "", IF(AND(LOWER(TRIM(K41))=LOWER(TRIM(PANEL!$L$2)), L41=PANEL!$I$2), MAX($O$4:O40)+1, "")) | P41: =IF(ISBLANK(A41), "", IF(OR(B41="Q1", B41="Q2"), B41, IF(ISNUMBER(B41), IF(DAY(B41)<=15, "Q1", "Q2"), IF(MID(TRIM(B41),3,1)="/", IF(VALUE(LEFT(TRIM(B41),2))<=15, "Q1", "Q2"), IF(MID(TRIM(B41),5,1)="-", IF(VALUE(MID(TRIM(B41),9,2))<=15, "Q1", "Q2"), "Q1"))))) -> Q2
A42: M-0201 | B42: 46286 | C42: 04:45 PM | D42: Gasto | E42: Transporte | F42: Pago fijo | G42: Parqueadero Trabajo Semana - Abono parcial | H42: 8500 | I42: No especificado | J42: No especificada | K42: septiembre | L42: 2026 | M42: Telegram | N42: PAGO_FIJO|F-0095|septiembre|2026 | O42: =IF(ISBLANK(A42), "", IF(AND(LOWER(TRIM(K42))=LOWER(TRIM(PANEL!$L$2)), L42=PANEL!$I$2), MAX($O$4:O41)+1, "")) | P42: =IF(ISBLANK(A42), "", IF(OR(B42="Q1", B42="Q2"), B42, IF(ISNUMBER(B42), IF(DAY(B42)<=15, "Q1", "Q2"), IF(MID(TRIM(B42),3,1)="/", IF(VALUE(LEFT(TRIM(B42),2))<=15, "Q1", "Q2"), IF(MID(TRIM(B42),5,1)="-", IF(VALUE(MID(TRIM(B42),9,2))<=15, "Q1", "Q2"), "Q1"))))) -> Q2
A43: M-0200 | B43: 46286 | C43: 12:34 PM | D43: Gasto | E43: Alimentación | F43: Lácteos y Colanta | G43: Factura Electrónica DIAN COOPERATIVA COLANTA 454A263995 | H43: 11998 | I43: Transferencia | J43: AyC Colanta | K43: septiembre | L43: 2026 | M43: Gmail | N43: GMAIL:1a0c507a4abf1b35|REF:454A263995 | O43: =IF(ISBLANK(A43), "", IF(AND(LOWER(TRIM(K43))=LOWER(TRIM(PANEL!$L$2)), L43=PANEL!$I$2), MAX($O$4:O42)+1, "")) | P43: =IF(ISBLANK(A43), "", IF(OR(B43="Q1", B43="Q2"), B43, IF(ISNUMBER(B43), IF(DAY(B43)<=15, "Q1", "Q2"), IF(MID(TRIM(B43),3,1)="/", IF(VALUE(LEFT(TRIM(B43),2))<=15, "Q1", "Q2"), IF(MID(TRIM(B43),5,1)="-", IF(VALUE(MID(TRIM(B43),9,2))<=15, "Q1", "Q2"), "Q1"))))) -> Q2
A44: M-0199 | B44: 46285 | C44: 09:33 PM | D44: Gasto | E44: Servicios | F44: Pago fijo | G44: Google One - Pago mensual | H44: 20000 | I44: No especificado | J44: No especificada | K44: septiembre | L44: 2026 | M44: Telegram | N44: PAGO_FIJO|F-0102|septiembre|2026 | O44: =IF(ISBLANK(A44), "", IF(AND(LOWER(TRIM(K44))=LOWER(TRIM(PANEL!$L$2)), L44=PANEL!$I$2), MAX($O$4:O43)+1, "")) | P44: =IF(ISBLANK(A44), "", IF(OR(B44="Q1", B44="Q2"), B44, IF(ISNUMBER(B44), IF(DAY(B44)<=15, "Q1", "Q2"), IF(MID(TRIM(B44),3,1)="/", IF(VALUE(LEFT(TRIM(B44),2))<=15, "Q1", "Q2"), IF(MID(TRIM(B44),5,1)="-", IF(VALUE(MID(TRIM(B44),9,2))<=15, "Q1", "Q2"), "Q1"))))) -> Q2
A45: M-0198 | B45: 46285 | C45: 09:32 PM | D45: Gasto | E45: Servicios | F45: Pago fijo | G45: EPM ENERGIA - Pago mensual | H45: 120000 | I45: No especificado | J45: No especificada | K45: septiembre | L45: 2026 | M45: Telegram | N45: PAGO_FIJO|F-0092|septiembre|2026 | O45: =IF(ISBLANK(A45), "", IF(AND(LOWER(TRIM(K45))=LOWER(TRIM(PANEL!$L$2)), L45=PANEL!$I$2), MAX($O$4:O44)+1, "")) | P45: =IF(ISBLANK(A45), "", IF(OR(B45="Q1", B45="Q2"), B45, IF(ISNUMBER(B45), IF(DAY(B45)<=15, "Q1", "Q2"), IF(MID(TRIM(B45),3,1)="/", IF(VALUE(LEFT(TRIM(B45),2))<=15, "Q1", "Q2"), IF(MID(TRIM(B45),5,1)="-", IF(VALUE(MID(TRIM(B45),9,2))<=15, "Q1", "Q2"), "Q1"))))) -> Q2
...

Sheet COLILLAS DE PAGO
A1: 📄 AUDITORÍA DE NÓMINA — COOPERATIVA COLANTA
A2: Registro histórico auditable de desprendibles quincenales y liquidación de prestaciones sociales Colanta
A4: ID Colilla | B4: Mes | C4: Año | D4: Quincena | E4: Período Liquidado | F4: Días | G4: Básico Quincenal ($) | H4: Extras y Recargos ($) | I4: Otros Devengados ($) | J4: TOTAL DEVENGADO ($) | K4: Salud EPS Sura ($) | L4: Pensión Porvenir ($) | M4: Fondo Empleados AyC ($) | N4: Otras Deducciones ($) | O4: NETO A COBRAR ($) | P4: Cuenta Consignación | Q4: Fecha Pago Real | R4: Estado | S4: Observaciones | T4: Ref. Documento
A5: CP-0018 | B5: septiembre | C5: 2026 | D5: Q2 | E5: 16/09/2026 al 30/09/2026 | F5: 15 | G5: 1627897 | H5: 572448 | I5: 95955 | J5: 2296300 | K5: 88014 | L5: 88014 | M5: 236121 | N5: 243873 | O5: 1640278 | P5: AyC Colanta | Q5: 46295 | R5: Pagado | S5: 2da Quincena Septiembre Periodo 18 | T5: Colilla_Pago_Periodo_18.pdf
A6: CP-0010 | B6: septiembre | C6: 2026 | D6: Q1 | E6: 01/09/2026 al 15/09/2026 | F6: 15 | G6: 1878342 | H6: 324238 | I6: 95956 | J6: 2298536 | K6: 88154 | L6: 88154 | M6: 236121 | N6: 183380 | O6: 1702727 | P6: AyC Colanta | Q6: 15/09/2026 | R6: Pagado | S6: 1ra Quincena Septiembre Periodo 17 | T6: Colilla_Pago_Periodo_17.pdf
A7: CP-0009 | B7: agosto | C7: 2026 | D7: Q2 | E7: 16/08/2026 al 31/08/2026 | F7: 15 | G7: 1878342 | H7: 420000 | I7: 402384 | J7: 2700726 | K7: 103935 | L7: 103935 | M7: 236121 | N7: 183380 | O7: 2073355 | P7: AyC Colanta | Q7: 31/08/2026 | R7: Pagado | S7: 2da Quincena Agosto Colanta | T7: Colilla_Agosto_Q2.pdf
A8: CP-0001 | B8: agosto | C8: 2026 | D8: Q1 | E8: 01/08/2026 al 15/08/2026 | F8: 15 | G8: 1878342 | H8: 220000 | I8: 197958 | J8: 2296300 | K8: 88037 | L8: 88037 | M8: 236121 | N8: 222067 | O8: 1662038 | P8: AyC Colanta | Q8: 15/08/2026 | R8: Pagado | S8: 1ra Quincena Agosto Colanta | T8: Colilla_Agosto_Q1.pdf
A9: CP-0008 | B9: julio | C9: 2026 | D9: Q2 | E9: 16/07/2026 al 31/07/2026 | F9: 15 | G9: 1878342 | H9: 120000 | I9: 107576 | J9: 2105918 | K9: 80143 | L9: 80143 | M9: 236121 | N9: 211709 | O9: 1497802 | P9: AyC Colanta | Q9: 31/07/2026 | R9: Pagado | S9: 2da Quincena Julio Colanta | T9: Colilla_Julio_Q2.pdf
A10: CP-0007 | B10: julio | C10: 2026 | D10: Q1 | E10: 01/07/2026 al 15/07/2026 | F10: 15 | G10: 1878342 | H10: 210000 | I10: 193461 | J10: 2281803 | K10: 87533 | L10: 87533 | M10: 236121 | N10: 196227 | O10: 1674389 | P10: AyC Colanta | Q10: 15/07/2026 | R10: Pagado | S10: 1ra Quincena Julio Colanta | T10: Colilla_Julio_Q1.pdf
A11: CP-0017 | B11: junio | C11: 2026 | D11: Q2 | E11: 16/06/2026 al 30/06/2026 | F11: 15 | G11: 1878342 | H11: 350000 | I11: 311658 | J11: 2540000 | K11: 90000 | L11: 90000 | M11: 236121 | N11: 184973 | O11: 1938906 | P11: AyC Colanta | Q11: 30/06/2026 | R11: Pagado | S11: 2da Quincena Junio Colanta | T11: Colilla_Junio_Q2.pdf
A12: CP-0016 | B12: junio | C12: 2026 | D12: Q1 | E12: 01/06/2026 al 15/06/2026 | F12: 15 | G12: 1878342 | H12: 450000 | I12: 1921658 | J12: 4250000 | K12: 110000 | L12: 110000 | M12: 236121 | N12: 274671 | O12: 3519208 | P12: AyC Colanta | Q12: 15/06/2026 | R12: Pagado | S12: 1ra Quincena Junio + Prima Colanta | T12: Colilla_Junio_Q1_Prima.pdf
A13: CP-0006 | B13: mayo | C13: 2026 | D13: Q2 | E13: 16/05/2026 al 31/05/2026 | F13: 15 | G13: 1878342 | H13: 120000 | I13: 107575 | J13: 2105917 | K13: 80143 | L13: 80143 | M13: 236121 | N13: 183380 | O13: 1526130 | P13: AyC Colanta | Q13: 31/05/2026 | R13: Pagado | S13: 2da Quincena Mayo Colanta | T13: Colilla_Mayo_Q2.pdf
A14: CP-0015 | B14: mayo | C14: 2026 | D14: Q1 | E14: 01/05/2026 al 15/05/2026 | F14: 15 | G14: 1878342 | H14: 180000 | I14: 181658 | J14: 2240000 | K14: 86000 | L14: 86000 | M14: 236121 | N14: 194256 | O14: 1637623 | P14: AyC Colanta | Q14: 15/05/2026 | R14: Pagado | S14: 1ra Quincena Mayo Colanta | T14: Colilla_Mayo_Q1.pdf
A15: CP-0014 | B15: abril | C15: 2026 | D15: Q2 | E15: 16/04/2026 al 30/04/2026 | F15: 15 | G15: 1878342 | H15: 150000 | I15: 151658 | J15: 2180000 | K15: 85000 | L15: 85000 | M15: 236121 | N15: 198389 | O15: 1575490 | P15: AyC Colanta | Q15: 30/04/2026 | R15: Pagado | S15: 2da Quincena Abril Colanta | T15: Colilla_Abril_Q2.pdf
A16: CP-0013 | B16: abril | C16: 2026 | D16: Q1 | E16: 01/04/2026 al 15/04/2026 | F16: 15 | G16: 1878342 | H16: 320000 | I16: 321658 | J16: 2520000 | K16: 92000 | L16: 92000 | M16: 236121 | N16: 181257 | O16: 1918622 | P16: AyC Colanta | Q16: 15/04/2026 | R16: Pagado | S16: 1ra Quincena Abril Colanta | T16: Colilla_Abril_Q1.pdf
A17: CP-0012 | B17: marzo | C17: 2026 | D17: Q2 | E17: 16/03/2026 al 31/03/2026 | F17: 15 | G17: 1878342 | H17: 240000 | I17: 241658 | J17: 2360000 | K17: 88000 | L17: 88000 | M17: 236121 | N17: 188963 | O17: 1758916 | P17: AyC Colanta | Q17: 31/03/2026 | R17: Pagado | S17: 2da Quincena Marzo Colanta | T17: Colilla_Marzo_Q2.pdf
... A22: CP-0003 | B22: enero | C22: 2026 | D22: Q1 | E22: 01/01/2026 al 15/01/2026 | F22: 15 | G22: 1878342 | H22: 550000 | I22: 558122 | J22: 2986464 | K22: 91518 | L22: 91518 | M22: 236121 | N22: 227445 | O22: 2339862 | P22: AyC Colanta | Q22: 15/01/2026 | R22: Pagado | S22: 1ra Quincena Enero Colanta | T22: Colilla_Enero_Q1.pdf
B23: PROYECCIÓN PRESTACIONAL LEGAL Y FONDOS ANUALES COLANTA
B24: Concepto Prestacional / Beneficio | E24: Base de Cálculo | G24: Fecha Legal Entrega | I24: Valor Proyectado ($) | K24: Destino Sugerido / Recomendación
B25: Prima Legal de Servicios (Junio) | E25: 50% Salario Promedio Semestre I | G25: 30 de Junio | I25: =AVERAGE(J4:J22) -> 2418909.1 | K25: Ahorro / Abono a compromisos
B26: Prima Legal de Servicios (Diciembre) | E26: 50% Salario Promedio Semestre II | G26: 20 de Diciembre | I26: =AVERAGE(J4:J22) -> 2418909.1 | K26: Fin de año y proyectos
B27: Ahorro Navideño Cooperativa Colanta | E27: $120.000 quincenal en nómina | G27: 01 de Diciembre | I27: =AHORROS!C9 -> 2160000 | K27: Entrega Fondo Colanta
B28: Cesantías Anuales de Ley | E28: 1 Mes de Salario Completo por Año | G28: 14 de Febrero (a Fondo) | I28: =AVERAGE(J4:J22)*2 -> 4837818.1 | K28: Consignación Fondo Porvenir
B29: Intereses a las Cesantías (12%) | E29: 12% Anual sobre Cesantías | G29: 31 de Enero (a Cuenta) | I29: =(AVERAGE(J4:J22)*2)*0.12 -> 580538.17 | K29: Nómina de enero
B30: TOTAL LIQUIDEZ EXTRA PRESTACIONAL Y FONDOS ESTIMADA (AÑO) | I30: =SUM(I25:I29) -> 12416174 | K30: Capital adicional para metas y patrimonio

Sheet AHORROS
A1: 🐷 FONDOS DE AHORRO Y APORTES — COOPERATIVA COLANTA
A2: Control de ahorros retenidos por nómina, fondo navideño y aportes cooperativos Colanta
A4: TOTAL ACUMULADO FONDOS COLANTA | C4: AHORRO MES SELECCIONADO (PANEL) | E4: FONDO NAVIDEÑO ACUMULADO
A5: =C12 -> 3931299 | C5: =B12 -> 0 | E5: =C9 -> 2160000
A7: Línea de Ahorro / Fondo | B7: Mes Seleccionado ($) | C7: Acumulado Total ($) | D7: % Participación | E7: Propósito / Destino
A8: Ahorro Ordinario | B8: =SUMIFS($E$14:$E$87, $D$14:$D$87, A8, $F$14:$F$87, PANEL!$L$2, $G$14:$G$87, PANEL!$I$2) -> 0 | C8: =SUMIF($D$14:$D$87, A8, $E$14:$E$87) -> 594000 | D8: =IFERROR(C8/$C$12, 0) -> 0.1510951 | E8: A la vista / Fondo de emergencia personal
A9: Ahorro Navideño | B9: =SUMIFS($E$14:$E$87, $D$14:$D$87, A9, $F$14:$F$87, PANEL!$L$2, $G$14:$G$87, PANEL!$I$2) -> 0 | C9: =SUMIF($D$14:$D$87, A9, $E$14:$E$87) -> 2160000 | D9: =IFERROR(C9/$C$12, 0) -> 0.54943671 | E9: Contractual / Entrega en diciembre Colanta
A10: Aportes Cooperativos | B10: =SUMIFS($E$14:$E$87, $D$14:$D$87, A10, $F$14:$F$87, PANEL!$L$2, $G$14:$G$87, PANEL!$I$2) -> 0 | C10: =SUMIF($D$14:$D$87, A10, $E$14:$E$87) -> 995083 | D10: =IFERROR(C10/$C$12, 0) -> 0.25311812 | E10: Capitalización obligatoria Colanta AyC
A11: Aporte Afiliación / Otros | B11: =SUMIFS($E$14:$E$87, $F$14:$F$87, PANEL!$L$2, $G$14:$G$87, PANEL!$I$2) - SUM(B8:B10) -> 0 | C11: =SUM($E$14:$E$87) - SUM(C8:C10) -> 182216 | D11: =IFERROR(C11/$C$12, 0) -> 0.046350074 | E11: Fondo y beneficios de asociado
A12: TOTAL FONDOS COLANTA | B12: =SUM(B8:B11) -> 0 | C12: =SUM(C8:C11) -> 3931299 | D12: =SUM(D8:D11) -> 1 | E12: Patrimonio acumulado Marlon Muñoz
A14: ID Descuento | B14: Fecha Nómina | C14: Colilla Ref | D14: Línea de Ahorro | E14: Monto Ahorrado ($) | F14: Mes | G14: Año | H14: Quincena | I14: Notas / Auditoría
A15: A-0001 | B15: 15/08/2026 | C15: Fondo de Empleados Colanta | D15: Ahorro Ordinario | E15: 33000 | F15: agosto | G15: 2026 | H15: Ref Colilla: CP-0001 | Ahorro Ordinario
A16: A-0002 | B16: 15/08/2026 | C16: Fondo de Empleados Colanta | D16: Ahorro Navideño | E16: 120000 | F16: agosto | G16: 2026 | H16: Ref Colilla: CP-0001 | Ahorro Navideño
A17: A-0003 | B17: 15/08/2026 | C17: Fondo de Empleados Colanta | D17: Aportes Cooperativos | E17: 37567 | F17: agosto | G17: 2026 | H17: Ref Colilla: CP-0001 | Aportes Cooperativos
A18: A-0004 | B18: 15/08/2026 | C18: Fondo de Empleados Colanta | D18: Otros Ahorros | E18: 45554 | F18: agosto | G18: 2026 | H18: Ref Colilla: CP-0001 | Otros Ahorros
A19: A-0005 | B19: 15/03/2026 | C19: Fondo de Empleados Colanta | D19: Ahorro Ordinario | E19: 33000 | F19: marzo | G19: 2026 | H19: IMPORT_HISTORICO_MARLON_2026-08-20
A20: A-0006 | B20: 15/03/2026 | C20: Fondo de Empleados Colanta | D20: Ahorro Navideño | E20: 120000 | F20: marzo | G20: 2026 | H20: IMPORT_HISTORICO_MARLON_2026-08-20
A21: A-0007 | B21: 15/03/2026 | C21: Fondo de Empleados Colanta | D21: Aportes Cooperativos | E21: 83121 | F21: marzo | G21: 2026 | H21: IMPORT_HISTORICO_MARLON_2026-08-20
A22: A-0008 | B22: 31/03/2026 | C22: Fondo de Empleados Colanta | D22: Ahorro Ordinario | E22: 33000 | F22: marzo | G22: 2026 | H22: IMPORT_HISTORICO_MARLON_2026-08-20
A23: A-0009 | B23: 31/03/2026 | C23: Fondo de Empleados Colanta | D23: Ahorro Navideño | E23: 120000 | F23: marzo | G23: 2026 | H23: IMPORT_HISTORICO_MARLON_2026-08-20
A24: A-0010 | B24: 31/03/2026 | C24: Fondo de Empleados Colanta | D24: Aportes Cooperativos | E24: 83121 | F24: marzo | G24: 2026 | H24: IMPORT_HISTORICO_MARLON_2026-08-20
A25: A-0011 | B25: 15/04/2026 | C25: Fondo de Empleados Colanta | D25: Ahorro Ordinario | E25: 33000 | F25: abril | G25: 2026 | H25: IMPORT_HISTORICO_MARLON_2026-08-20
A26: A-0012 | B26: 15/04/2026 | C26: Fondo de Empleados Colanta | D26: Ahorro Navideño | E26: 120000 | F26: abril | G26: 2026 | H26: IMPORT_HISTORICO_MARLON_2026-08-20
... A63: A-0049 | B63: 31/08/2026 | C63: Fondo de Empleados Colanta | D63: Aportes Cooperativos | E63: 37567 | F63: agosto | G63: 2026 | H63: ref colilla: cp-0009 | aportes cooperativos
A64: A-0050 | B64: 15/09/2026 | C64: Fondo de Empleados Colanta | D64: Ahorro Ordinario | E64: 33000 | F64: septiembre | G64: 2026 | H64: Ref Colilla: CP-0010 | Ahorro Ordinario | ⏰ 11:03 PM | I64: 11:03 PM
A65: A-0051 | B65: 15/09/2026 | C65: Fondo de Empleados Colanta | D65: Ahorro Navideño | E65: 120000 | F65: septiembre | G65: 2026 | H65: Ref Colilla: CP-0010 | Ahorro Navideño | ⏰ 11:03 PM | I65: 11:03 PM
A66: A-0052 | B66: 15/09/2026 | C66: Fondo de Empleados Colanta | D66: Aportes Cooperativos | E66: 37567 | F66: septiembre | G66: 2026 | H66: Ref Colilla: CP-0010 | Aportes Cooperativos | ⏰ 11:03 PM | I66: 11:03 PM
A67: A-0053 | B67: 15/09/2026 | C67: Fondo de Empleados Colanta | D67: Aporte Afiliación Cooperativa | E67: 45554 | F67: septiembre | G67: 2026 | H67: Ref Colilla: CP-0010 | Aporte Afiliación Cooperativa | ⏰ 11:03 PM | I67: 11:03 PM
A68: A-0056 | B68: 46295 | C68: Fondo de Empleados Colanta | D68: Aportes Cooperativos | E68: 37567 | F68: septiembre | G68: 2026 | H68: ref colilla: cp-0018 | aportes cooperativos
A69: A-0057 | B69: 46295 | C69: Fondo de Empleados Colanta | D69: Otros Ahorros | E69: 45554 | F69: septiembre | G69: 2026 | H69: ref colilla: cp-0018 | otros ahorros
A70: A-0058 | B70: 46295 | C70: Fondo de Empleados Colanta | D70: Ahorro Ordinario | E70: 33000 | F70: septiembre | G70: 2026 | H70: Ref Colilla: CP-0018 | Ahorro Ordinario
A71: A-0059 | B71: 46295 | C71: Fondo de Empleados Colanta | D71: Ahorro Navideño | E71: 120000 | F71: septiembre | G71: 2026 | H71: Ref Colilla: CP-0018 | Ahorro Navideño
A72: A-0060 | B72: 46295 | C72: Fondo de Empleados Colanta | D72: Aporte Afiliación Cooperativa | E72: 45554 | F72: septiembre | G72: 2026 | H72: Ref Colilla: CP-0018 | Aporte Afiliación Cooperativa

Sheet CONTROL FIJOS
A1: ="📌 CONTROL DE COMPROMISOS FIJOS — " & UPPER(PANEL!L2) & " " & PANEL!I2 -> 📌 CONTROL DE COMPROMISOS FIJOS — OCTUBRE 2026
A2: Sincronizado automáticamente con el mes y año seleccionados en el Panel Principal
A4: TOTAL CUOTAS MES | D4: TOTAL ABONADO / PAGADO | G4: SALDO PENDIENTE | J4: COMPROMISOS Q1 (DÍA <=15)
A5: =SUM(E10:E26) -> 2611000 | D5: =SUM(F10:F26) -> 54000 | G5: =SUM(I10:I26) -> 2557000 | J5: =SUMIFS(I10:I26, D10:D26, "<=15") -> 1332000
A9: ID | B9: Concepto / Servicio | C9: Categoría | D9: Día Cobro | E9: Cuota Base ($) | F9: Abonado Mes ($) | G9: Estado | H9: Fecha Último Pago | I9: Saldo Pendiente ($) | J9: Prioridad | K9: Medio de Pago | L9: Notas / Referencia
A10: {=IFERROR(INDEX('HISTORICO FIJOS'!$A$3:$A$204, MATCH(1, 'HISTORICO FIJOS'!$P$3:$P$204, 0)), "")} -> F-0107 | B10: {=IFERROR(INDEX('HISTORICO FIJOS'!$B$3:$B$204, MATCH(1, 'HISTORICO FIJOS'!$P$3:$P$204, 0)), "")} -> EPM ENERGIA | C10: {=IFERROR(INDEX('HISTORICO FIJOS'!$C$3:$C$204, MATCH(1, 'HISTORICO FIJOS'!$P$3:$P$204, 0)), "")} -> Servicios | D10: {=IFERROR(INDEX('HISTORICO FIJOS'!$D$3:$D$204, MATCH(1, 'HISTORICO FIJOS'!$P$3:$P$204, 0)), "")} -> 15 | E10: {=IFERROR(INDEX('HISTORICO FIJOS'!$E$4:$E$250, MATCH(1, 'HISTORICO FIJOS'!$P$4:$P$250, 0)), "")} -> 177000 | F10: {=IFERROR(INDEX('HISTORICO FIJOS'!$F$4:$F$250, MATCH(1, 'HISTORICO FIJOS'!$P$4:$P$250, 0)), "")} -> 0 | G10: =IF(A10="","",IF(N(F10)>=E10,"🟢 Pagado",IF(N(F10)>0,"🟡 Abono Parcial","🔴 Pendiente"))) -> 🔴 Pendiente | H10: {=IFERROR(INDEX('HISTORICO FIJOS'!$G$4:$G$250, MATCH(1, 'HISTORICO FIJOS'!$P$4:$P$250, 0)), "")} | I10: =IF(A10="","",MAX(0, E10-N(F10))) -> 177000 | J10: {=IFERROR(INDEX('HISTORICO FIJOS'!$L$3:$L$204, MATCH(1, 'HISTORICO FIJOS'!$P$3:$P$204, 0)), "")} -> Media | K10: {=IFERROR(INDEX('HISTORICO FIJOS'!$M$3:$M$204, MATCH(1, 'HISTORICO FIJOS'!$P$3:$P$204, 0)), "")} -> Transferencia | L10: {=IFERROR(INDEX('HISTORICO FIJOS'!$O$3:$O$204, MATCH(1, 'HISTORICO FIJOS'!$P$3:$P$204, 0)), "")}
A11: {=IFERROR(INDEX('HISTORICO FIJOS'!$A$3:$A$204, MATCH(2, 'HISTORICO FIJOS'!$P$3:$P$204, 0)), "")} -> F-0108 | B11: {=IFERROR(INDEX('HISTORICO FIJOS'!$B$3:$B$204, MATCH(2, 'HISTORICO FIJOS'!$P$3:$P$204, 0)), "")} -> COMIDA | C11: {=IFERROR(INDEX('HISTORICO FIJOS'!$C$3:$C$204, MATCH(2, 'HISTORICO FIJOS'!$P$3:$P$204, 0)), "")} -> Alimentación | D11: {=IFERROR(INDEX('HISTORICO FIJOS'!$D$3:$D$204, MATCH(2, 'HISTORICO FIJOS'!$P$3:$P$204, 0)), "")} -> 15 | E11: {=IFERROR(INDEX('HISTORICO FIJOS'!$E$3:$E$204, MATCH(2, 'HISTORICO FIJOS'!$P$3:$P$204, 0)), "")} -> 850000 | F11: {=IFERROR(INDEX('HISTORICO FIJOS'!$F$3:$F$204, MATCH(2, 'HISTORICO FIJOS'!$P$3:$P$204, 0)), "")} -> 0 | G11: =IF(A11="","",IF(N(F11)>=E11,"🟢 Pagado",IF(N(F11)>0,"🟡 Abono Parcial","🔴 Pendiente"))) -> 🔴 Pendiente | H11: {=IFERROR(INDEX('HISTORICO FIJOS'!$G$3:$G$204, MATCH(2, 'HISTORICO FIJOS'!$P$3:$P$204, 0)), "")} | I11: =IF(A11="","",MAX(0, E11-N(F11))) -> 850000 | J11: {=IFERROR(INDEX('HISTORICO FIJOS'!$L$3:$L$204, MATCH(2, 'HISTORICO FIJOS'!$P$3:$P$204, 0)), "")} -> Media | K11: {=IFERROR(INDEX('HISTORICO FIJOS'!$M$3:$M$204, MATCH(2, 'HISTORICO FIJOS'!$P$3:$P$204, 0)), "")} -> Transferencia | L11: {=IFERROR(INDEX('HISTORICO FIJOS'!$O$3:$O$204, MATCH(2, 'HISTORICO FIJOS'!$P$3:$P$204, 0)), "")}
A12: {=IFERROR(INDEX('HISTORICO FIJOS'!$A$3:$A$204, MATCH(3, 'HISTORICO FIJOS'!$P$3:$P$204, 0)), "")} -> F-0109 | B12: {=IFERROR(INDEX('HISTORICO FIJOS'!$B$3:$B$204, MATCH(3, 'HISTORICO FIJOS'!$P$3:$P$204, 0)), "")} -> Internet Tigo | C12: {=IFERROR(INDEX('HISTORICO FIJOS'!$C$3:$C$204, MATCH(3, 'HISTORICO FIJOS'!$P$3:$P$204, 0)), "")} -> Servicios | D12: {=IFERROR(INDEX('HISTORICO FIJOS'!$D$3:$D$204, MATCH(3, 'HISTORICO FIJOS'!$P$3:$P$204, 0)), "")} -> 15 | E12: {=IFERROR(INDEX('HISTORICO FIJOS'!$E$3:$E$204, MATCH(3, 'HISTORICO FIJOS'!$P$3:$P$204, 0)), "")} -> 120000 | F12: {=IFERROR(INDEX('HISTORICO FIJOS'!$F$3:$F$204, MATCH(3, 'HISTORICO FIJOS'!$P$3:$P$204, 0)), "")} -> 0 | G12: =IF(A12="","",IF(N(F12)>=E12,"🟢 Pagado",IF(N(F12)>0,"🟡 Abono Parcial","🔴 Pendiente"))) -> 🔴 Pendiente | H12: {=IFERROR(INDEX('HISTORICO FIJOS'!$G$3:$G$204, MATCH(3, 'HISTORICO FIJOS'!$P$3:$P$204, 0)), "")} | I12: =IF(A12="","",MAX(0, E12-N(F12))) -> 120000 | J12: {=IFERROR(INDEX('HISTORICO FIJOS'!$L$3:$L$204, MATCH(3, 'HISTORICO FIJOS'!$P$3:$P$204, 0)), "")} -> Media | K12: {=IFERROR(INDEX('HISTORICO FIJOS'!$M$3:$M$204, MATCH(3, 'HISTORICO FIJOS'!$P$3:$P$204, 0)), "")} -> Transferencia | L12: {=IFERROR(INDEX('HISTORICO FIJOS'!$O$3:$O$204, MATCH(3, 'HISTORICO FIJOS'!$P$3:$P$204, 0)), "")}
A13: {=IFERROR(INDEX('HISTORICO FIJOS'!$A$3:$A$204, MATCH(4, 'HISTORICO FIJOS'!$P$3:$P$204, 0)), "")} -> F-0110 | B13: {=IFERROR(INDEX('HISTORICO FIJOS'!$B$3:$B$204, MATCH(4, 'HISTORICO FIJOS'!$P$3:$P$204, 0)), "")} -> Parqueadero Trabajo Semana | C13: {=IFERROR(INDEX('HISTORICO FIJOS'!$C$3:$C$204, MATCH(4, 'HISTORICO FIJOS'!$P$3:$P$204, 0)), "")} -> Transporte | D13: {=IFERROR(INDEX('HISTORICO FIJOS'!$D$3:$D$204, MATCH(4, 'HISTORICO FIJOS'!$P$3:$P$204, 0)), "")} -> 15 | E13: {=IFERROR(INDEX('HISTORICO FIJOS'!$E$3:$E$204, MATCH(4, 'HISTORICO FIJOS'!$P$3:$P$204, 0)), "")} -> 40000 | F13: {=IFERROR(INDEX('HISTORICO FIJOS'!$F$3:$F$204, MATCH(4, 'HISTORICO FIJOS'!$P$3:$P$204, 0)), "")} -> 0 | G13: =IF(A13="","",IF(N(F13)>=E13,"🟢 Pagado",IF(N(F13)>0,"🟡 Abono Parcial","🔴 Pendiente"))) -> 🔴 Pendiente | H13: {=IFERROR(INDEX('HISTORICO FIJOS'!$G$3:$G$204, MATCH(4, 'HISTORICO FIJOS'!$P$3:$P$204, 0)), "")} | I13: =IF(A13="","",MAX(0, E13-N(F13))) -> 40000 | J13: {=IFERROR(INDEX('HISTORICO FIJOS'!$L$3:$L$204, MATCH(4, 'HISTORICO FIJOS'!$P$3:$P$204, 0)), "")} -> Media | K13: {=IFERROR(INDEX('HISTORICO FIJOS'!$M$3:$M$204, MATCH(4, 'HISTORICO FIJOS'!$P$3:$P$204, 0)), "")} -> Transferencia | L13: {=IFERROR(INDEX('HISTORICO FIJOS'!$O$3:$O$204, MATCH(4, 'HISTORICO FIJOS'!$P$3:$P$204, 0)), "")}
A14: {=IFERROR(INDEX('HISTORICO FIJOS'!$A$3:$A$204, MATCH(5, 'HISTORICO FIJOS'!$P$3:$P$204, 0)), "")} -> F-0111 | B14: {=IFERROR(INDEX('HISTORICO FIJOS'!$B$3:$B$204, MATCH(5, 'HISTORICO FIJOS'!$P$3:$P$204, 0)), "")} -> Cuota Audifonos Samsung | C14: {=IFERROR(INDEX('HISTORICO FIJOS'!$C$3:$C$204, MATCH(5, 'HISTORICO FIJOS'!$P$3:$P$204, 0)), "")} -> Otros | D14: {=IFERROR(INDEX('HISTORICO FIJOS'!$D$3:$D$204, MATCH(5, 'HISTORICO FIJOS'!$P$3:$P$204, 0)), "")} -> 15 | E14: {=IFERROR(INDEX('HISTORICO FIJOS'!$E$3:$E$204, MATCH(5, 'HISTORICO FIJOS'!$P$3:$P$204, 0)), "")} -> 50000 | F14: {=IFERROR(INDEX('HISTORICO FIJOS'!$F$3:$F$204, MATCH(5, 'HISTORICO FIJOS'!$P$3:$P$204, 0)), "")} -> 0 | G14: =IF(A14="","",IF(N(F14)>=E14,"🟢 Pagado",IF(N(F14)>0,"🟡 Abono Parcial","🔴 Pendiente"))) -> 🔴 Pendiente | H14: {=IFERROR(INDEX('HISTORICO FIJOS'!$G$3:$G$204, MATCH(5, 'HISTORICO FIJOS'!$P$3:$P$204, 0)), "")} | I14: =IF(A14="","",MAX(0, E14-N(F14))) -> 50000 | J14: {=IFERROR(INDEX('HISTORICO FIJOS'!$L$3:$L$204, MATCH(5, 'HISTORICO FIJOS'!$P$3:$P$204, 0)), "")} -> Media | K14: {=IFERROR(INDEX('HISTORICO FIJOS'!$M$3:$M$204, MATCH(5, 'HISTORICO FIJOS'!$P$3:$P$204, 0)), "")} -> Transferencia | L14: {=IFERROR(INDEX('HISTORICO FIJOS'!$O$3:$O$204, MATCH(5, 'HISTORICO FIJOS'!$P$3:$P$204, 0)), "")}
A15: {=IFERROR(INDEX('HISTORICO FIJOS'!$A$3:$A$204, MATCH(6, 'HISTORICO FIJOS'!$P$3:$P$204, 0)), "")} -> F-0112 | B15: {=IFERROR(INDEX('HISTORICO FIJOS'!$B$3:$B$204, MATCH(6, 'HISTORICO FIJOS'!$P$3:$P$204, 0)), "")} -> PARQUEADERO MOTO | C15: {=IFERROR(INDEX('HISTORICO FIJOS'!$C$3:$C$204, MATCH(6, 'HISTORICO FIJOS'!$P$3:$P$204, 0)), "")} -> Moto | D15: {=IFERROR(INDEX('HISTORICO FIJOS'!$D$3:$D$204, MATCH(6, 'HISTORICO FIJOS'!$P$3:$P$204, 0)), "")} -> 15 | E15: {=IFERROR(INDEX('HISTORICO FIJOS'!$E$3:$E$204, MATCH(6, 'HISTORICO FIJOS'!$P$3:$P$204, 0)), "")} -> 60000 | F15: {=IFERROR(INDEX('HISTORICO FIJOS'!$F$3:$F$204, MATCH(6, 'HISTORICO FIJOS'!$P$3:$P$204, 0)), "")} -> 0 | G15: =IF(A15="","",IF(N(F15)>=E15,"🟢 Pagado",IF(N(F15)>0,"🟡 Abono Parcial","🔴 Pendiente"))) -> 🔴 Pendiente | H15: {=IFERROR(INDEX('HISTORICO FIJOS'!$G$3:$G$204, MATCH(6, 'HISTORICO FIJOS'!$P$3:$P$204, 0)), "")} | I15: =IF(A15="","",MAX(0, E15-N(F15))) -> 60000 | J15: {=IFERROR(INDEX('HISTORICO FIJOS'!$L$3:$L$204, MATCH(6, 'HISTORICO FIJOS'!$P$3:$P$204, 0)), "")} -> Media | K15: {=IFERROR(INDEX('HISTORICO FIJOS'!$M$3:$M$204, MATCH(6, 'HISTORICO FIJOS'!$P$3:$P$204, 0)), "")} -> Efectivo | L15: {=IFERROR(INDEX('HISTORICO FIJOS'!$O$3:$O$204, MATCH(6, 'HISTORICO FIJOS'!$P$3:$P$204, 0)), "")}
A16: {=IFERROR(INDEX('HISTORICO FIJOS'!$A$3:$A$204, MATCH(7, 'HISTORICO FIJOS'!$P$3:$P$204, 0)), "")} -> F-0113 | B16: {=IFERROR(INDEX('HISTORICO FIJOS'!$B$3:$B$204, MATCH(7, 'HISTORICO FIJOS'!$P$3:$P$204, 0)), "")} -> Gasolina Moto | C16: {=IFERROR(INDEX('HISTORICO FIJOS'!$C$3:$C$204, MATCH(7, 'HISTORICO FIJOS'!$P$3:$P$204, 0)), "")} -> Moto | D16: {=IFERROR(INDEX('HISTORICO FIJOS'!$D$3:$D$204, MATCH(7, 'HISTORICO FIJOS'!$P$3:$P$204, 0)), "")} -> 15 | E16: {=IFERROR(INDEX('HISTORICO FIJOS'!$E$3:$E$204, MATCH(7, 'HISTORICO FIJOS'!$P$3:$P$204, 0)), "")} -> 35000 | F16: {=IFERROR(INDEX('HISTORICO FIJOS'!$F$3:$F$204, MATCH(7, 'HISTORICO FIJOS'!$P$3:$P$204, 0)), "")} -> 0 | G16: =IF(A16="","",IF(N(F16)>=E16,"🟢 Pagado",IF(N(F16)>0,"🟡 Abono Parcial","🔴 Pendiente"))) -> 🔴 Pendiente | H16: {=IFERROR(INDEX('HISTORICO FIJOS'!$G$3:$G$204, MATCH(7, 'HISTORICO FIJOS'!$P$3:$P$204, 0)), "")} | I16: =IF(A16="","",MAX(0, E16-N(F16))) -> 35000 | J16: {=IFERROR(INDEX('HISTORICO FIJOS'!$L$3:$L$204, MATCH(7, 'HISTORICO FIJOS'!$P$3:$P$204, 0)), "")} -> Media | K16: {=IFERROR(INDEX('HISTORICO FIJOS'!$M$3:$M$204, MATCH(7, 'HISTORICO FIJOS'!$P$3:$P$204, 0)), "")} -> Transferencia | L16: {=IFERROR(INDEX('HISTORICO FIJOS'!$O$3:$O$204, MATCH(7, 'HISTORICO FIJOS'!$P$3:$P$204, 0)), "")}
A17: {=IFERROR(INDEX('HISTORICO FIJOS'!$A$3:$A$204, MATCH(8, 'HISTORICO FIJOS'!$P$3:$P$204, 0)), "")} -> F-0114 | B17: {=IFERROR(INDEX('HISTORICO FIJOS'!$B$3:$B$204, MATCH(8, 'HISTORICO FIJOS'!$P$3:$P$204, 0)), "")} -> Spotify | C17: {=IFERROR(INDEX('HISTORICO FIJOS'!$C$3:$C$204, MATCH(8, 'HISTORICO FIJOS'!$P$3:$P$204, 0)), "")} -> Entretenimiento | D17: {=IFERROR(INDEX('HISTORICO FIJOS'!$D$3:$D$204, MATCH(8, 'HISTORICO FIJOS'!$P$3:$P$204, 0)), "")} -> 15 | E17: {=IFERROR(INDEX('HISTORICO FIJOS'!$E$3:$E$204, MATCH(8, 'HISTORICO FIJOS'!$P$3:$P$204, 0)), "")} -> 10100 | F17: {=IFERROR(INDEX('HISTORICO FIJOS'!$F$3:$F$204, MATCH(8, 'HISTORICO FIJOS'!$P$3:$P$204, 0)), "")} -> 10100 | G17: =IF(A17="","",IF(N(F17)>=E17,"🟢 Pagado",IF(N(F17)>0,"🟡 Abono Parcial","🔴 Pendiente"))) -> 🟢 Pagado | H17: {=IFERROR(INDEX('HISTORICO FIJOS'!$G$3:$G$204, MATCH(8, 'HISTORICO FIJOS'!$P$3:$P$204, 0)), "")} -> 46310 | I17: =IF(A17="","",MAX(0, E17-N(F17))) -> 0 | J17: {=IFERROR(INDEX('HISTORICO FIJOS'!$L$3:$L$204, MATCH(8, 'HISTORICO FIJOS'!$P$3:$P$204, 0)), "")} -> Media | K17: {=IFERROR(INDEX('HISTORICO FIJOS'!$M$3:$M$204, MATCH(8, 'HISTORICO FIJOS'!$P$3:$P$204, 0)), "")} -> Tarjeta Nequi | L17: {=IFERROR(INDEX('HISTORICO FIJOS'!$O$3:$O$204, MATCH(8, 'HISTORICO FIJOS'!$P$3:$P$204, 0)), "")} -> Renovación automática Google Play GPA.3333-4099-9556-15284..13
